<?xml version="1.0" encoding="UTF-8"?>
<!-- Generated by org.testng.reporters.JUnitReportReporter -->
<testsuite hostname="UMESH" failures="1" tests="3" name="pages.test.PageTest2" time="16.672" errors="0" timestamp="2024-01-06T12:01:42 IST" skipped="0">
  <testcase classname="pages.test.PageTest2" name="test1" time="6.262"/>
  <system-out>
    <![CDATA[adding logs to test1]]>
  </system-out>
  <testcase classname="pages.test.PageTest2" name="test4" time="6.546"/>
  <system-out/>
  <testcase classname="pages.test.PageTest2" name="test3" time="3.864">
    <failure message="expected [true] but found [false]" type="java.lang.AssertionError">
      <![CDATA[java.lang.AssertionError: expected [true] but found [false]
at org.testng.Assert.fail(Assert.java:99)
at org.testng.Assert.failNotEquals(Assert.java:1037)
at org.testng.Assert.assertTrue(Assert.java:45)
at org.testng.Assert.assertTrue(Assert.java:55)
at pages.test.PageTest2.test3(PageTest2.java:20)
at java.base/jdk.internal.reflect.DirectMethodHandleAccessor.invoke(DirectMethodHandleAccessor.java:104)
at java.base/java.lang.reflect.Method.invoke(Method.java:578)
at org.testng.internal.MethodInvocationHelper.invokeMethod(MethodInvocationHelper.java:133)
at org.testng.internal.InvokeMethodRunnable.runOne(InvokeMethodRunnable.java:45)
at org.testng.internal.InvokeMethodRunnable.call(InvokeMethodRunnable.java:73)
at org.testng.internal.InvokeMethodRunnable.call(InvokeMethodRunnable.java:11)
at java.base/java.util.concurrent.FutureTask.run(FutureTask.java:317)
at java.base/java.util.concurrent.ThreadPoolExecutor.runWorker(ThreadPoolExecutor.java:1144)
at java.base/java.util.concurrent.ThreadPoolExecutor$Worker.run(ThreadPoolExecutor.java:642)
at java.base/java.lang.Thread.run(Thread.java:1623)
]]>
    </failure>
  </testcase> <!-- test3 -->
  <system-out/>
</testsuite> <!-- pages.test.PageTest2 -->
